# Sample error log file

Traceback (most recent call last):
  File "/Library/Python/2.7/site-packages/Django-1.5-py2.7.egg/django/core/handlers/base.py", line 103, in get_response
    resolver_match = resolver.resolve(request.path_info)
  File "/Library/Python/2.7/site-packages/Django-1.5-py2.7.egg/django/core/urlresolvers.py", line 319, in resolve
    for pattern in self.url_patterns:
  File "/Library/Python/2.7/site-packages/Django-1.5-py2.7.egg/django/core/urlresolvers.py", line 347, in url_patterns
    patterns = getattr(self.urlconf_module, "urlpatterns", self.urlconf_module)
  File "/Library/Python/2.7/site-packages/Django-1.5-py2.7.egg/django/core/urlresolvers.py", line 342, in urlconf_module
    self._urlconf_module = import_module(self.urlconf_name)
  File "/Library/Python/2.7/site-packages/Django-1.5-py2.7.egg/django/utils/importlib.py", line 35, in import_module
    __import__(name)
  File "/Users/Dani/Documents/Projects/Golismero_2.0/src/golismero_2/sample_site/core/urls.py", line 38, in <module>
    url(r'^', include('apps.root_files.urls')),
  File "/Library/Python/2.7/site-packages/Django-1.5-py2.7.egg/django/conf/urls/__init__.py", line 25, in include
    urlconf_module = import_module(urlconf_module)
  File "/Library/Python/2.7/site-packages/Django-1.5-py2.7.egg/django/utils/importlib.py", line 35, in import_module
    __import__(name)